#include <exception>
int main()
{
	throw std::exception();
	return 1;
}
